<?xml version="1.0" ?>
<!-- =================================================================================== -->
<!-- |    This document was autogenerated by xacro from whole_robot_with_gripper.xacro | -->
<!-- |    EDITING THIS FILE BY HAND IS NOT RECOMMENDED                                 | -->
<!-- =================================================================================== -->
<robot name="holonomic_base">
  <!-- "" -->
  <link name="base_link"/>
  <link name="m_body">
    <inertial>
      <origin rpy="0 0 0" xyz="-0.0107573806983678 -0.000121111379146382 0.168820068401291"/>
      <mass value="7.75262327008847"/>
      <inertia ixx="0.0674364406464489" ixy="2.6530001859869E-06" ixz="-2.02885454828053E-06" iyy="0.0607129183001536" iyz="-2.82546028667119E-08" izz="0.117886359812438"/>
    </inertial>
    <visual>
      <origin rpy="0 0 0" xyz="0 0 0"/>
      <geometry>
        <mesh filename="package://swerve_description/meshes/holonomic/base_link.STL"/>
      </geometry>
      <material name="">
        <color rgba="0.752941176470588 0.752941176470588 0.752941176470588 1"/>
      </material>
    </visual>
    <collision>
      <origin rpy="0 0 0" xyz="0 0 0"/>
      <geometry>
        <mesh filename="package://swerve_description/meshes/holonomic/base_link.STL"/>
      </geometry>
    </collision>
  </link>
  <joint name="xbase_arm_joint" type="fixed">
    <origin rpy="0 0 0" xyz="0.2625 0 0.2745"/>
    <parent link="base_link"/>
    <child link="x_arm_link"/>
  </joint>
  <joint name="base_link_to_body" type="fixed">
    <parent link="base_link"/>
    <child link="m_body"/>
    <origin xyz="0 0 0"/>
  </joint>
  <link name="leg_fl">
    <inertial>
      <origin rpy="0 0 0" xyz="0.0 0.0 -0.041346"/>
      <mass value="0.1509"/>
      <inertia ixx="8.621E-05" ixy="-2.6953E-09" ixz="-8.1387E-10" iyy="5.4519E-05" iyz="1.5042E-09" izz="6.6419E-05"/>
    </inertial>
    <visual>
      <origin rpy="0 0 0" xyz="0 0 0"/>
      <geometry>
        <mesh filename="package://swerve_description/meshes/holonomic/turn_front_left_link.STL"/>
      </geometry>
      <material name="">
        <color rgba="0.75294 0.75294 0.75294 1"/>
      </material>
    </visual>
    <collision>
      <origin rpy="0 0 0" xyz="0 0 0"/>
      <geometry>
        <mesh filename="package://swerve_description/meshes/holonomic/turn_front_left_link.STL"/>
      </geometry>
    </collision>
  </link>
  <joint name="left_front_steer_joint" type="revolute">
    <origin rpy="3.141592653589793 0 3.141592653589793" xyz="0.285 0.215 0.1705"/>
    <parent link="base_link"/>
    <child link="leg_fl"/>
    <axis xyz="0 0 1"/>
    <limit effort="20.0" lower="-3.341" upper="3.341" velocity="5.76"/>
    <safety_controller k_position="100" k_velocity="100" soft_lower_limit="-3.141" soft_upper_limit="3.141"/>
    <joint_properties damping="1.0" friction="5.0"/>
  </joint>
  <transmission name="leg_fl_trans">
    <type>transmission_interface/SimpleTransmission</type>
    <actuator name="$leg_fl_steering">
      <mechanicalReduction>1</mechanicalReduction>
    </actuator>
    <joint name="left_front_steer_joint">
      <hardwareInterface>hardware_interface/VelocityJointInterface</hardwareInterface>
    </joint>
  </transmission>
  <link name="leg_fr">
    <inertial>
      <origin rpy="0 0 0" xyz="-2.4774E-06 4.2768E-06 -0.041346"/>
      <mass value="0.1509"/>
      <inertia ixx="8.621E-05" ixy="-2.6953E-09" ixz="8.1387E-10" iyy="5.4519E-05" iyz="-1.5042E-09" izz="6.6419E-05"/>
    </inertial>
    <visual>
      <origin rpy="0 0 0" xyz="0 0 0"/>
      <geometry>
        <mesh filename="package://swerve_description/meshes/holonomic/turn_front_right_link.STL"/>
      </geometry>
      <material name="">
        <color rgba="0.75294 0.75294 0.75294 1"/>
      </material>
    </visual>
    <collision>
      <origin rpy="0 0 0" xyz="0 0 0"/>
      <geometry>
        <mesh filename="package://swerve_description/meshes/holonomic/turn_front_right_link.STL"/>
      </geometry>
    </collision>
  </link>
  <joint name="right_front_steer_joint" type="revolute">
    <origin rpy="3.14159265358979 0 3.14159265358979" xyz="0.285 -0.215 0.1705"/>
    <!-- <origin xyz="0.585 -0.215 0.1705" rpy="3.14159265358979 0 3.14159265358979" /> -->
    <parent link="base_link"/>
    <child link="leg_fr"/>
    <axis xyz="0 0 1"/>
    <limit effort="20.0" lower="-3.341" upper="3.341" velocity="5.76"/>
    <safety_controller k_position="100" k_velocity="100" soft_lower_limit="-3.141" soft_upper_limit="3.141"/>
    <joint_properties damping="1.0" friction="5.0"/>
  </joint>
  <transmission name="leg_fr_trans">
    <type>transmission_interface/SimpleTransmission</type>
    <actuator name="$leg_fr_steering">
      <mechanicalReduction>1</mechanicalReduction>
    </actuator>
    <joint name="right_front_steer_joint">
      <hardwareInterface>hardware_interface/VelocityJointInterface</hardwareInterface>
    </joint>
  </transmission>
  <link name="leg_rl">
    <inertial>
      <origin rpy="0 0 0" xyz="2.47739936293234E-06 -0.00390427681696906 0.0596537478356015"/>
      <mass value="0.150899435444674"/>
      <inertia ixx="8.62104557625573E-05" ixy="-2.69534706876987E-09" ixz="-8.13867681148677E-10" iyy="5.45191084176943E-05" iyz="1.50418273401286E-09" izz="6.64192852433824E-05"/>
    </inertial>
    <visual>
      <origin rpy="0 0 0" xyz="0 0 0"/>
      <geometry>
        <mesh filename="package://swerve_description/meshes/holonomic/turn_back_left_link.STL"/>
      </geometry>
      <material name="">
        <color rgba="0.752941176470588 0.752941176470588 0.752941176470588 1"/>
      </material>
    </visual>
    <collision>
      <origin rpy="0 0 0" xyz="0 0 0"/>
      <geometry>
        <mesh filename="package://swerve_description/meshes/holonomic/turn_back_left_link.STL"/>
      </geometry>
    </collision>
  </link>
  <joint name="left_back_steer_joint" type="revolute">
    <origin rpy="-3.1416 0 0" xyz="-0.285 0.215 0.1705"/>
    <!-- <origin xyz="-0.585 0.215 0.1705" rpy="-3.1416 0 0" /> -->
    <parent link="base_link"/>
    <child link="leg_rl"/>
    <axis xyz="0 0 1"/>
    <limit effort="20.0" lower="-3.341" upper="3.341" velocity="5.76"/>
    <safety_controller k_position="100" k_velocity="100" soft_lower_limit="-3.141" soft_upper_limit="3.141"/>
    <joint_properties damping="1.0" friction="5.0"/>
  </joint>
  <transmission name="leg_rl_trans">
    <type>transmission_interface/SimpleTransmission</type>
    <actuator name="$leg_rl_steering">
      <mechanicalReduction>1</mechanicalReduction>
    </actuator>
    <joint name="left_back_steer_joint">
      <hardwareInterface>hardware_interface/VelocityJointInterface</hardwareInterface>
    </joint>
  </transmission>
  <link name="leg_rr">
    <inertial>
      <origin rpy="0 0 0" xyz="-2.4774E-06 4.2768E-06 -0.041346"/>
      <mass value="0.1509"/>
      <inertia ixx="8.621E-05" ixy="-2.6953E-09" ixz="8.1387E-10" iyy="5.4519E-05" iyz="-1.5042E-09" izz="6.6419E-05"/>
    </inertial>
    <visual>
      <origin rpy="0 0 0" xyz="0 0 0"/>
      <geometry>
        <mesh filename="package://swerve_description/meshes/holonomic/turn_back_right_link.STL"/>
      </geometry>
      <material name="">
        <color rgba="0.75294 0.75294 0.75294 1"/>
      </material>
    </visual>
    <collision>
      <origin rpy="0 0 0" xyz="0 0 0"/>
      <geometry>
        <mesh filename="package://swerve_description/meshes/holonomic/turn_back_right_link.STL"/>
      </geometry>
    </collision>
  </link>
  <joint name="right_back_steer_joint" type="revolute">
    <origin rpy="3.1416 0 0" xyz="-0.285 -0.215 0.1705"/>
    <!-- <origin xyz="-0.585 -0.215 0.1705" rpy="3.1416 0 0" /> -->
    <parent link="base_link"/>
    <child link="leg_rr"/>
    <axis xyz="0 0 1"/>
    <limit effort="20.0" lower="-3.341" upper="3.341" velocity="5.76"/>
    <safety_controller k_position="100" k_velocity="100" soft_lower_limit="-3.141" soft_upper_limit="3.141"/>
    <joint_properties damping="1.0" friction="5.0"/>
  </joint>
  <transmission name="leg_rr_trans">
    <type>transmission_interface/SimpleTransmission</type>
    <actuator name="$leg_rr_steering">
      <mechanicalReduction>1</mechanicalReduction>
    </actuator>
    <joint name="right_back_steer_joint">
      <hardwareInterface>hardware_interface/VelocityJointInterface</hardwareInterface>
    </joint>
  </transmission>
  <link name="wheel_fl">
    <inertial>
      <origin rpy="0 0 0" xyz="-6.7203E-07 -0.0039185 1.1995E-07"/>
      <mass value="1.7978"/>
      <inertia ixx="0.0022135" ixy="1.588E-07" ixz="2.5603E-08" iyy="0.003666" iyz="-1.0669E-08" izz="0.0022134"/>
    </inertial>
    <visual>
      <origin rpy="0 0 0" xyz="0 0 0"/>
      <geometry>
        <mesh filename="package://swerve_description/meshes/holonomic/wheel_front_left_link.STL"/>
      </geometry>
      <material name="">
        <color rgba="1 0.75294 0.75294 1"/>
      </material>
    </visual>
    <collision>
      <origin rpy="0 0 0" xyz="0 0 0"/>
      <geometry>
        <mesh filename="package://swerve_description/meshes/holonomic/wheel_front_left_link.STL"/>
      </geometry>
    </collision>
  </link>
  <joint name="left_front_wheel_joint" type="continuous">
    <origin rpy="-1.5708 1.5708 0" xyz="0 0.0039 0.101"/>
    <parent link="leg_fl"/>
    <child link="wheel_fl"/>
    <axis xyz="0 0 1"/>
    <limit effort="1000" velocity="11.52"/>
    <safety_controller k_position="100" k_velocity="100"/>
    <joint_properties damping="1.0" friction="5.0"/>
  </joint>
  <transmission name="wheel_fl_trans">
    <type>transmission_interface/SimpleTransmission</type>
    <actuator name="wheel_fl_drive">
      <mechanicalReduction>1</mechanicalReduction>
    </actuator>
    <joint name="left_front_wheel_joint">
      <hardwareInterface>hardware_interface/VelocityJointInterface</hardwareInterface>
    </joint>
  </transmission>
  <gazebo reference="wheel_fl">
    <mu1 value="0.7"/>
    <mu2 value="0.5"/>
    <kp value="300000.0"/>
    <kd value="600.0"/>
  </gazebo>
  <link name="wheel_fr">
    <inertial>
      <origin rpy="0 0 0" xyz="6.7203E-07 0.0039185 1.1995E-07"/>
      <mass value="1.7978"/>
      <inertia ixx="0.0022135" ixy="1.588E-07" ixz="-2.5603E-08" iyy="0.003666" iyz="1.0669E-08" izz="0.0022134"/>
    </inertial>
    <visual>
      <origin rpy="0 0 0" xyz="0 0 0"/>
      <geometry>
        <mesh filename="package://swerve_description/meshes/holonomic/wheel_front_right_link.STL"/>
      </geometry>
      <material name="">
        <color rgba="1 0.75294 0.75294 1"/>
      </material>
    </visual>
    <collision>
      <origin rpy="0 0 0" xyz="0 0 0"/>
      <geometry>
        <mesh filename="package://swerve_description/meshes/holonomic/wheel_front_right_link.STL"/>
      </geometry>
    </collision>
  </link>
  <joint name="right_front_wheel_joint" type="continuous">
    <origin rpy="1.5707963267949 1.5707963267949 0" xyz="0 -0.0039 0.101"/>
    <parent link="leg_fr"/>
    <child link="wheel_fr"/>
    <axis xyz="0 0 1"/>
    <limit effort="1000" velocity="11.52"/>
    <safety_controller k_position="100" k_velocity="100"/>
    <joint_properties damping="1.0" friction="5.0"/>
  </joint>
  <transmission name="wheel_fr_trans">
    <type>transmission_interface/SimpleTransmission</type>
    <actuator name="wheel_fr_drive">
      <mechanicalReduction>1</mechanicalReduction>
    </actuator>
    <joint name="right_front_wheel_joint">
      <hardwareInterface>hardware_interface/VelocityJointInterface</hardwareInterface>
    </joint>
  </transmission>
  <gazebo reference="wheel_fr">
    <mu1 value="0.7"/>
    <mu2 value="0.5"/>
    <kp value="300000.0"/>
    <kd value="600.0"/>
  </gazebo>
  <link name="wheel_rl">
    <inertial>
      <origin rpy="0 0 0" xyz="-6.7203E-07 -0.0039185 1.1995E-07"/>
      <mass value="1.7978"/>
      <inertia ixx="0.0022135" ixy="1.588E-07" ixz="2.5603E-08" iyy="0.003666" iyz="-1.0669E-08" izz="0.0022134"/>
    </inertial>
    <visual>
      <origin rpy="0 0 0" xyz="0 0 0"/>
      <geometry>
        <mesh filename="package://swerve_description/meshes/holonomic/wheel_back_left_link.STL"/>
      </geometry>
      <material name="">
        <color rgba="1 0.75294 0.75294 1"/>
      </material>
    </visual>
    <collision>
      <origin rpy="0 0 0" xyz="0 0 0"/>
      <geometry>
        <mesh filename="package://swerve_description/meshes/holonomic/wheel_back_left_link.STL"/>
      </geometry>
    </collision>
  </link>
  <joint name="left_back_wheel_joint" type="continuous">
    <origin rpy="1.5708 1.5708 0" xyz="0 -0.0039 0.101"/>
    <parent link="leg_rl"/>
    <child link="wheel_rl"/>
    <axis xyz="0 0 1"/>
    <limit effort="1000" velocity="11.52"/>
    <safety_controller k_position="100" k_velocity="100"/>
    <joint_properties damping="1.0" friction="5.0"/>
  </joint>
  <transmission name="wheel_rl_trans">
    <type>transmission_interface/SimpleTransmission</type>
    <actuator name="wheel_rl_drive">
      <mechanicalReduction>1</mechanicalReduction>
    </actuator>
    <joint name="left_back_wheel_joint">
      <hardwareInterface>hardware_interface/VelocityJointInterface</hardwareInterface>
    </joint>
  </transmission>
  <gazebo reference="wheel_rl">
    <mu1 value="0.7"/>
    <mu2 value="0.5"/>
    <kp value="300000.0"/>
    <kd value="600.0"/>
  </gazebo>
  <link name="wheel_rr">
    <inertial>
      <origin rpy="0 0 0" xyz="6.7203E-07 0.0039185 1.1995E-07"/>
      <mass value="1.7978"/>
      <inertia ixx="0.0022135" ixy="1.588E-07" ixz="-2.5603E-08" iyy="0.003666" iyz="1.0669E-08" izz="0.0022134"/>
    </inertial>
    <visual>
      <origin rpy="0 0 0" xyz="0 0 0"/>
      <geometry>
        <mesh filename="package://swerve_description/meshes/holonomic/wheel_back_right_link.STL"/>
      </geometry>
      <material name="">
        <color rgba="1 0.75294 0.75294 1"/>
      </material>
    </visual>
    <collision>
      <origin rpy="0 0 0" xyz="0 0 0"/>
      <geometry>
        <mesh filename="package://swerve_description/meshes/holonomic/wheel_back_right_link.STL"/>
      </geometry>
    </collision>
  </link>
  <joint name="right_back_wheel_joint" type="continuous">
    <origin rpy="-1.5707963267949 1.5707963267949 0" xyz="0 0.0039 0.101"/>
    <parent link="leg_rr"/>
    <child link="wheel_rr"/>
    <axis xyz="0 0 1"/>
    <limit effort="1000" velocity="11.52"/>
    <safety_controller k_position="100" k_velocity="100"/>
    <joint_properties damping="1.0" friction="5.0"/>
  </joint>
  <transmission name="wheel_rr_trans">
    <type>transmission_interface/SimpleTransmission</type>
    <actuator name="wheel_rr_drive">
      <mechanicalReduction>1</mechanicalReduction>
    </actuator>
    <joint name="right_back_wheel_joint">
      <hardwareInterface>hardware_interface/VelocityJointInterface</hardwareInterface>
    </joint>
  </transmission>
  <gazebo reference="wheel_rr">
    <mu1 value="0.7"/>
    <mu2 value="0.5"/>
    <kp value="300000.0"/>
    <kd value="600.0"/>
  </gazebo>
  <link name="x_arm_link">
    <inertial>
      <origin rpy="0 0 0" xyz="-0.000648 -0.000166 0.084487"/>
      <mass value="1.697"/>
      <inertia ixx="0.004622" ixy="9E-06" ixz="6E-05" iyy="0.004495" iyz="9E-06" izz="0.002079"/>
    </inertial>
    <visual>
      <origin rpy="0 0 0" xyz="0 0 0"/>
      <geometry>
        <mesh filename="package://swerve_description/meshes/jaco/base_link.STL"/>
      </geometry>
      <material name="">
        <color rgba="0.75294 0.75294 0.75294 1"/>
      </material>
    </visual>
    <collision>
      <origin rpy="0 0 0" xyz="0 0 0"/>
      <geometry>
        <mesh filename="package://swerve_description/meshes/jaco/base_link.STL"/>
      </geometry>
    </collision>
  </link>
  <link name="shoulder_link">
    <inertial>
      <origin rpy="0 0 0" xyz="-2.3E-05 -0.010364 -0.07336"/>
      <mass value="1.377"/>
      <inertia ixx="0.00457" ixy="1E-06" ixz="2E-06" iyy="0.004831" iyz="0.000448" izz="0.001409"/>
    </inertial>
    <visual>
      <origin rpy="0 0 0" xyz="0 0 0"/>
      <geometry>
        <mesh filename="package://swerve_description/meshes/jaco/shoulder_link.STL"/>
      </geometry>
      <material name="">
        <color rgba="0.75294 0.75294 0.75294 1"/>
      </material>
    </visual>
    <collision>
      <origin rpy="0 0 0" xyz="0 0 0"/>
      <geometry>
        <mesh filename="package://swerve_description/meshes/jaco/shoulder_link.STL"/>
      </geometry>
    </collision>
  </link>
  <joint name="SH_JOINT_1" type="revolute">
    <origin rpy="-3.1416 0.0 0.0" xyz="0 0 0.15643"/>
    <parent link="x_arm_link"/>
    <child link="shoulder_link"/>
    <axis xyz="0 0 1"/>
    <limit effort="39.0" lower="-6.28" upper="6.28" velocity="1.3963"/>
    <safety_controller k_position="100" k_velocity="100" soft_lower_limit="-6.2" soft_upper_limit="6.2"/>
    <joint_properties damping="1.0" friction="5.0"/>
  </joint>
  <link name="bicep_link">
    <inertial>
      <origin rpy="0 0 0" xyz="3.5E-05 -0.208207 -0.01889"/>
      <mass value="1.262"/>
      <inertia ixx="0.046752" ixy="-9E-06" ixz="0" iyy="0.00085" iyz="-9.8E-05" izz="0.047188"/>
    </inertial>
    <visual>
      <origin rpy="0 0 0" xyz="0 0 0"/>
      <geometry>
        <mesh filename="package://swerve_description/meshes/jaco/bicep_link.STL"/>
      </geometry>
      <material name="">
        <color rgba="0.75294 0.75294 0.75294 1"/>
      </material>
    </visual>
    <collision>
      <origin rpy="0 0 0" xyz="0 0 0"/>
      <geometry>
        <mesh filename="package://swerve_description/meshes/jaco/bicep_link.STL"/>
      </geometry>
    </collision>
  </link>
  <joint name="SH_JOINT_2" type="revolute">
    <origin rpy="1.5708 0.0 0.0" xyz="0 0.005375 -0.12838"/>
    <parent link="shoulder_link"/>
    <child link="bicep_link"/>
    <axis xyz="0 0 1"/>
    <limit effort="39.0" lower="-2.24" upper="2.24" velocity="1.3963"/>
    <safety_controller k_position="100" k_velocity="100" soft_lower_limit="-2.24" soft_upper_limit="2.24"/>
    <joint_properties damping="1.0" friction="5.0"/>
  </joint>
  <link name="forearm_link">
    <inertial>
      <origin rpy="0 0 0" xyz="1.8E-05 0.076168 -0.01397"/>
      <mass value="0.93"/>
      <inertia ixx="0.008292" ixy="-1E-06" ixz="0" iyy="0.000628" iyz="0.000432" izz="0.008464"/>
    </inertial>
    <visual>
      <origin rpy="0 0 0" xyz="0 0 0"/>
      <geometry>
        <mesh filename="package://swerve_description/meshes/jaco/forearm_link.STL"/>
      </geometry>
      <material name="">
        <color rgba="0.75294 0.75294 0.75294 1"/>
      </material>
    </visual>
    <collision>
      <origin rpy="0 0 0" xyz="0 0 0"/>
      <geometry>
        <mesh filename="package://swerve_description/meshes/jaco/forearm_link.STL"/>
      </geometry>
    </collision>
  </link>
  <joint name="SH_JOINT_3" type="revolute">
    <origin rpy="3.1416 0 0" xyz="0 -0.41 0"/>
    <parent link="bicep_link"/>
    <child link="forearm_link"/>
    <axis xyz="0 0 1"/>
    <limit effort="39.0" lower="-2.57" upper="2.57" velocity="1.3963"/>
    <safety_controller k_position="100" k_velocity="100" soft_lower_limit="-2.57" soft_upper_limit="2.57"/>
    <joint_properties damping="1.0" friction="5.0"/>
  </joint>
  <link name="spherical_wrist_1_link">
    <inertial>
      <origin rpy="0 0 0" xyz="-1E-06 0.008486 -0.062937"/>
      <mass value="0.6781"/>
      <inertia ixx="0.001645" ixy="0" ixz="0" iyy="0.001666" iyz="-0.000234" izz="0.000389"/>
    </inertial>
    <visual>
      <origin rpy="0 0 0" xyz="0 0 0"/>
      <geometry>
        <mesh filename="package://swerve_description/meshes/jaco/spherical_wrist_1_link.STL"/>
      </geometry>
      <material name="">
        <color rgba="0.75294 0.75294 0.75294 1"/>
      </material>
    </visual>
    <collision>
      <origin rpy="0 0 0" xyz="0 0 0"/>
      <geometry>
        <mesh filename="package://swerve_description/meshes/jaco/spherical_wrist_1_link.STL"/>
      </geometry>
    </collision>
  </link>
  <joint name="SH_JOINT_4" type="revolute">
    <origin rpy="1.5708 0.0 0.0" xyz="0 0.20843 -0.006375"/>
    <parent link="forearm_link"/>
    <child link="spherical_wrist_1_link"/>
    <axis xyz="0 0 1"/>
    <limit effort="9.0" lower="-6.28" upper="6.28" velocity="1.2218"/>
    <safety_controller k_position="100" k_velocity="100" soft_lower_limit="-6.18" soft_upper_limit="6.18"/>
    <joint_properties damping="1.0" friction="5.0"/>
  </joint>
  <link name="spherical_wrist_2_link">
    <inertial>
      <origin rpy="0 0 0" xyz="-1E-06 0.046429 -0.008704"/>
      <mass value="0.678"/>
      <inertia ixx="0.001685" ixy="0" ixz="0" iyy="0.0004" iyz="0.000255" izz="0.001696"/>
    </inertial>
    <visual>
      <origin rpy="0 0 0" xyz="0 0 0"/>
      <geometry>
        <mesh filename="package://swerve_description/meshes/jaco/spherical_wrist_2_link.STL"/>
      </geometry>
      <material name="">
        <color rgba="0.75294 0.75294 0.75294 1"/>
      </material>
    </visual>
    <collision>
      <origin rpy="0 0 0" xyz="0 0 0"/>
      <geometry>
        <mesh filename="package://swerve_description/meshes/jaco/spherical_wrist_2_link.STL"/>
      </geometry>
    </collision>
  </link>
  <joint name="SH_JOINT_5" type="revolute">
    <origin rpy="-1.5708 0.0 0.0" xyz="0 -0.00017505 -0.10593"/>
    <parent link="spherical_wrist_1_link"/>
    <child link="spherical_wrist_2_link"/>
    <axis xyz="0 0 1"/>
    <limit effort="9.0" lower="-2.09" upper="2.09" velocity="1.2218"/>
    <safety_controller k_position="100" k_velocity="100" soft_lower_limit="-2.09" soft_upper_limit="2.09"/>
    <joint_properties damping="1.0" friction="5.0"/>
  </joint>
  <link name="bracelet_link">
    <inertial>
      <origin rpy="0 0 0" xyz="0.000281 0.011402 -0.029798"/>
      <mass value="0.5"/>
      <inertia ixx="0.000587" ixy="3E-06" ixz="3E-06" iyy="0.000369" iyz="-0.000118" izz="0.000609"/>
    </inertial>
    <visual>
      <origin rpy="0 0 0" xyz="0 0 0"/>
      <geometry>
        <mesh filename="package://swerve_description/meshes/jaco/bracelet_with_vision_link.STL"/>
      </geometry>
      <material name="">
        <color rgba="0.75294 0.75294 0.75294 1"/>
      </material>
    </visual>
    <collision>
      <origin rpy="0 0 0" xyz="0 0 0"/>
      <geometry>
        <mesh filename="package://swerve_description/meshes/jaco/bracelet_with_vision_link.STL"/>
      </geometry>
    </collision>
  </link>
  <joint name="SH_JOINT_6" type="revolute">
    <origin rpy="1.5708 0.0 0.0" xyz="0 0.10593 -0.00017505"/>
    <parent link="spherical_wrist_2_link"/>
    <child link="bracelet_link"/>
    <axis xyz="0 0 1"/>
    <limit effort="9.0" lower="-3.341" upper="3.341" velocity="1.2218"/>
    <safety_controller k_position="100" k_velocity="100" soft_lower_limit="-3.141" soft_upper_limit="3.141"/>
    <joint_properties damping="1.0" friction="5.0"/>
  </joint>
  <link name="end_effector_link"/>
  <joint name="end_effector" type="fixed">
    <origin rpy="3.14159265358979 1.09937075168372E-32 3.14159265358979" xyz="0 0 -0.2215250000000001"/>
    <parent link="bracelet_link"/>
    <child link="end_effector_link"/>
    <axis xyz="0 0 0"/>
  </joint>
  <link name="camera_link"/>
  <joint name="camera_module" type="fixed">
    <origin rpy="3.14159265358979 3.14159265358979 0" xyz="0 0.05639 -0.00305"/>
    <parent link="end_effector_link"/>
    <child link="camera_link"/>
  </joint>
  <link name="camera_depth_frame"/>
  <joint name="depth_module" type="fixed">
    <origin rpy="3.14159265358979 3.14159265358979 0" xyz="0.0275 0.066 -0.00305"/>
    <parent link="end_effector_link"/>
    <child link="camera_depth_frame"/>
  </joint>
  <link name="camera_color_frame"/>
  <joint name="color_module" type="fixed">
    <origin rpy="3.14159265358979 3.14159265358979 0" xyz="0 0.05639 -0.00305"/>
    <parent link="end_effector_link"/>
    <child link="camera_color_frame"/>
  </joint>
  <transmission name="joint_1_transmission">
    <type>transmission_interface/SimpleTransmission</type>
    <actuator name="joint_1_motor">
      <mechanicalReduction>1</mechanicalReduction>
    </actuator>
    <joint name="SH_JOINT_1">
      <hardwareInterface>hardware_interface/VelocityJointInterface</hardwareInterface>
    </joint>
  </transmission>
  <transmission name="joint_2_transmission">
    <type>transmission_interface/SimpleTransmission</type>
    <joint name="SH_JOINT_2">
      <hardwareInterface>hardware_interface/VelocityJointInterface</hardwareInterface>
    </joint>
    <actuator name="joint_2_motor">
      <mechanicalReduction>1</mechanicalReduction>
    </actuator>
  </transmission>
  <transmission name="joint_3_transmission">
    <type>transmission_interface/SimpleTransmission</type>
    <joint name="SH_JOINT_3">
      <hardwareInterface>hardware_interface/VelocityJointInterface</hardwareInterface>
    </joint>
    <actuator name="joint_3_motor">
      <mechanicalReduction>1</mechanicalReduction>
    </actuator>
  </transmission>
  <transmission name="joint_4_transmission">
    <type>transmission_interface/SimpleTransmission</type>
    <joint name="SH_JOINT_4">
      <hardwareInterface>hardware_interface/VelocityJointInterface</hardwareInterface>
    </joint>
    <actuator name="joint_4_motor">
      <mechanicalReduction>1</mechanicalReduction>
    </actuator>
  </transmission>
  <transmission name="joint_5_transmission">
    <type>transmission_interface/SimpleTransmission</type>
    <joint name="SH_JOINT_5">
      <hardwareInterface>hardware_interface/VelocityJointInterface</hardwareInterface>
    </joint>
    <actuator name="joint_5_motor">
      <mechanicalReduction>1</mechanicalReduction>
    </actuator>
  </transmission>
  <transmission name="joint_6_transmission">
    <type>transmission_interface/SimpleTransmission</type>
    <joint name="SH_JOINT_6">
      <hardwareInterface>hardware_interface/VelocityJointInterface</hardwareInterface>
    </joint>
    <actuator name="joint_6_motor">
      <mechanicalReduction>1</mechanicalReduction>
    </actuator>
  </transmission>
  <transmission name="left_outer_knuckle_joint_trans">
    <type>transmission_interface/SimpleTransmission</type>
    <joint name="left_outer_knuckle_joint">
      <hardwareInterface>hardware_interface/VelocityJointInterface</hardwareInterface>
    </joint>
    <actuator name="left_outer_knuckle_joint_motor">
      <mechanicalReduction>1</mechanicalReduction>
      <hardwareInterface>hardware_interface/VelocityJointInterface</hardwareInterface>
    </actuator>
  </transmission>
  <!-- Mimic joint plugin -->
  <gazebo>
    <plugin filename="libroboticsgroup_upatras_gazebo_mimic_joint_plugin.so" name="mimic_dh_robotics_ag95_3">
      <joint>left_outer_knuckle_joint</joint>
      <mimicJoint>right_outer_knuckle_joint</mimicJoint>
      <multiplier>1</multiplier>
      <offset>0.0</offset>
      <robotNamespace>swerve_base</robotNamespace>
      <maxEffort>5.0</maxEffort>
        <hasPID/>
    </plugin>
  </gazebo>
  <gazebo reference="ag95_base_link">
    <material>Gazebo/Grey</material>
    <kp>1000000.0</kp>
    <kd>1.0</kd>
    <mu1>1.16</mu1>
    <mu2>1.16</mu2>
    <maxVel>0.0</maxVel>
    <minDepth>0.003</minDepth>
  </gazebo>
  <gazebo reference="ag95_body">
    <material>Gazebo/Black</material>
    <kp>1000000.0</kp>
    <kd>1.0</kd>
    <mu1>1.16</mu1>
    <mu2>1.16</mu2>
    <maxVel>0.0</maxVel>
    <minDepth>0.003</minDepth>
  </gazebo>
  <gazebo reference="left_outer_knuckle">
    <material>Gazebo/Black</material>
    <kp>1000000.0</kp>
    <kd>1.0</kd>
    <mu1>1.16</mu1>
    <mu2>1.16</mu2>
    <maxVel>0.0</maxVel>
    <minDepth>0.003</minDepth>
  </gazebo>
  <gazebo reference="left_inner_knuckle">
    <material>Gazebo/Black</material>
    <kp>1000000.0</kp>
    <kd>1.0</kd>
    <mu1>1.16</mu1>
    <mu2>1.16</mu2>
    <maxVel>0.0</maxVel>
    <minDepth>0.003</minDepth>
  </gazebo>
  <gazebo reference="left_finger">
    <material>Gazebo/Grey</material>
    <kp>1000000.0</kp>
    <kd>1.0</kd>
    <mu1>1.16</mu1>
    <mu2>1.16</mu2>
    <maxVel>0.0</maxVel>
    <minDepth>0.003</minDepth>
  </gazebo>
  <gazebo reference="right_outer_knuckle">
    <material>Gazebo/Black</material>
    <kp>1000000.0</kp>
    <kd>1.0</kd>
    <mu1>1.16</mu1>
    <mu2>1.16</mu2>
    <maxVel>0.0</maxVel>
    <minDepth>0.003</minDepth>
  </gazebo>
  <gazebo reference="right_inner_knuckle">
    <material>Gazebo/Black</material>
    <kp>1000000.0</kp>
    <kd>1.0</kd>
    <mu1>1.16</mu1>
    <mu2>1.16</mu2>
    <maxVel>0.0</maxVel>
    <minDepth>0.003</minDepth>
  </gazebo>
  <gazebo reference="right_finger">
    <material>Gazebo/Grey</material>
    <kp>1000000.0</kp>
    <kd>1.0</kd>
    <mu1>1.16</mu1>
    <mu2>1.16</mu2>
    <maxVel>0.0</maxVel>
    <minDepth>0.003</minDepth>
  </gazebo>
  <gazebo reference="left_outer_knuckle_joint">
    <implicitSpringDamper>true</implicitSpringDamper>
  </gazebo>
  <gazebo reference="left_finger_joint">
    <implicitSpringDamper>true</implicitSpringDamper>
  </gazebo>
  <gazebo reference="left_inner_knuckle_joint">
    <implicitSpringDamper>true</implicitSpringDamper>
  </gazebo>
  <gazebo reference="left_inner_knuckle_to_finger_joint">
    <implicitSpringDamper>true</implicitSpringDamper>
  </gazebo>
  <gazebo reference="right_outer_knuckle_joint">
    <implicitSpringDamper>true</implicitSpringDamper>
  </gazebo>
  <gazebo reference="right_finger_joint">
    <implicitSpringDamper>true</implicitSpringDamper>
  </gazebo>
  <gazebo reference="right_inner_knuckle_joint">
    <implicitSpringDamper>true</implicitSpringDamper>
  </gazebo>
  <gazebo reference="right_inner_knuckle_to_finger_joint">
    <implicitSpringDamper>true</implicitSpringDamper>
  </gazebo>
  <!-- base link flange -->
  <link name="ag95_base_link">
    <!-- <inertial>
        <origin xyz="7.892486664218268e-13 9.73814800116557e-05 0.0030311891257515876" rpy="0 0 0" />
        <mass value="0.18321316702693136" />
        <inertia ixx="4e-05" iyy="0.000121" izz="0.000158" ixy="0.0" iyz="0.0" ixz="-0.0" />
      </inertial> -->
    <inertial>
      <origin rpy="0 0 0" xyz="7.892486664218268e-13 9.73814800116557e-05 0.0030311891257515876"/>
      <mass value="0.05335674905975589"/>
      <inertia ixx="1.1649107960000001e-05" ixy="0.0" ixz="-0.0" iyy="3.5238551579e-05" iyz="0.0" izz="4.6013976442e-05"/>
    </inertial>
    <visual>
      <origin rpy="0 0 0" xyz="0 0 0"/>
      <geometry>
        <mesh filename="package://swerve_description/meshes/gripper/visual/base_link.stl" scale="0.001 0.001 0.001"/>
      </geometry>
      <material name="">
        <color rgba="0.792156862745098 0.819607843137255 0.933333333333333 1"/>
      </material>
    </visual>
    <collision>
      <origin rpy="0 0 0" xyz="0 0 0"/>
      <geometry>
        <mesh filename="package://swerve_description/meshes/gripper/collision/base_link.stl" scale="0.001 0.001 0.001"/>
      </geometry>
    </collision>
  </link>
  <!-- main body of gripper -->
  <link name="ag95_body">
    <!-- <inertial>
        <origin xyz="0.040363309423792425 0.014263796342398428 0.04377145101823153" rpy="0 0 0" />
        <mass value="2.681074820833332" />
        <inertia ixx="0.003857" iyy="0.004463" izz="0.001562" ixy="-3e-06" iyz="-2e-06" ixz="-9e-06" />
      </inertial> -->
    <inertial>
      <origin rpy="0 0 0" xyz="0.040363309423792425 0.014263796342398428 0.04377145101823153"/>
      <mass value="0.7808032509181286"/>
      <inertia ixx="0.001123265235043" ixy="-8.736830970000001e-07" ixz="-2.621049291e-06" iyy="0.001299749220637" iyz="-5.82455398e-07" izz="0.00045489766583800003"/>
    </inertial>
    <visual>
      <origin rpy="0 0 0" xyz="0.0405 0.0143 -0.0147"/>
      <geometry>
        <mesh filename="package://swerve_description/meshes/gripper/visual/gripper_body.stl" scale="0.001 0.001 0.001"/>
      </geometry>
      <material name="">
        <color rgba="0.1 0.1 0.1 1"/>
      </material>
    </visual>
    <collision>
      <origin rpy="0 0 0" xyz="0.0405 0.0143 -0.0147"/>
      <geometry>
        <mesh filename="package://swerve_description/meshes/gripper/collision/gripper_body.stl" scale="0.001 0.001 0.001"/>
      </geometry>
    </collision>
  </link>
  <joint name="ag95_body_joint" type="fixed">
    <origin rpy="0 0 0" xyz="-0.0405 -0.0143 0.0147"/>
    <parent link="ag95_base_link"/>
    <child link="ag95_body"/>
  </joint>
  <link name="left_outer_knuckle">
    <inertial>
      <origin rpy="0 0 0" xyz="0.027678515816713697 0.008750002359538555 -4.432690447753185e-07"/>
      <mass value="0.0589066057773107"/>
      <inertia ixx="1e-06" ixy="0.0" ixz="-0.0" iyy="1.7e-05" iyz="0.0" izz="1.7e-05"/>
    </inertial>
    <!-- <inertial>
          <origin xyz="0.027678515816713697 0.008750002359538555 -4.432690447753185e-07" rpy="0 0 0" />
          <mass value="${0.0589066057773107*0.44684369179}" />
          <inertia ixx="${1e-06*0.44684369179}" iyy="${1.7e-05*0.44684369179}" izz="${1.7e-05*0.44684369179}" ixy="${0.0*0.44684369179}" iyz="${0.0*0.44684369179}" ixz="${-0.0*0.44684369179}" />
        </inertial> -->
    <visual>
      <origin rpy="0 0 0" xyz="-0.036673 0.00875 -0.098336"/>
      <geometry>
        <mesh filename="package://swerve_description/meshes/gripper/visual/outer_knuckle.stl" scale="0.001 0.001 0.001"/>
      </geometry>
      <material name="">
        <color rgba="0.1 0.1 0.1 1"/>
      </material>
    </visual>
    <collision>
      <origin rpy="0 0 0" xyz="-0.036673 0.00875 -0.098336"/>
      <geometry>
        <mesh filename="package://swerve_description/meshes/gripper/collision/outer_knuckle.stl" scale="0.001 0.001 0.001"/>
      </geometry>
    </collision>
  </link>
  <link name="left_inner_knuckle">
    <inertial>
      <origin rpy="0 0 0" xyz="-0.001773347637755853 0.025399999999162655 0.028950024725163018"/>
      <mass value="0.07116672022913799"/>
      <inertia ixx="3.7e-05" ixy="0.0" ixz="0.0" iyy="1.7e-05" iyz="-0.0" izz="2.1e-05"/>
    </inertial>
    <!-- <inertial>
          <origin xyz="-0.001773347637755853 0.025399999999162655 0.028950024725163018" rpy="0 0 0" />
          <mass value="${0.07116672022913799*0.44684369179}" />
          <inertia ixx="${3.7e-05*0.44684369179}" iyy="${1.7e-05*0.44684369179}" izz="${2.1e-05*0.44684369179}" ixy="${0.0*0.44684369179}" iyz="${-0.0*0.44684369179}" ixz="${0.0*0.44684369179}" />
        </inertial> -->
    <visual>
      <origin rpy="0 0 0" xyz="-0.016 0.0254 -0.10586"/>
      <geometry>
        <mesh filename="package://swerve_description/meshes/gripper/visual/inner_knuckle.stl" scale="0.001 0.001 0.001"/>
      </geometry>
      <material name="">
        <color rgba="0.1 0.1 0.1 1"/>
      </material>
    </visual>
    <collision>
      <origin rpy="0 0 0" xyz="-0.016 0.0254 -0.10586"/>
      <geometry>
        <mesh filename="package://swerve_description/meshes/gripper/collision/inner_knuckle.stl" scale="0.001 0.001 0.001"/>
      </geometry>
    </collision>
  </link>
  <link name="left_finger">
    <inertial>
      <origin rpy="0 0 0" xyz="-0.013763205176003518 0.008750002316393751 0.007315452388518454"/>
      <mass value="0.035304126564626004"/>
      <inertia ixx="2e-06" ixy="0.0" ixz="1e-06" iyy="4e-06" iyz="-0.0" izz="3e-06"/>
    </inertial>
    <!-- <inertial>
          <origin xyz="-0.013763205176003518 0.008750002316393751 0.007315452388518454" rpy="0 0 0" />
          <mass value="${0.035304126564626004*0.14953484502}" />
          <inertia ixx="${2e-06*0.14953484502}" iyy="${4e-06*0.14953484502}" izz="${3e-06*0.14953484502}" ixy="${0.0*0.14953484502}" iyz="${-0.0*0.14953484502}" ixz="${1e-06*0.14953484502}" />
        </inertial> -->
    <visual>
      <origin rpy="0 0 0" xyz="-0.091673 0.00875 -0.098336"/>
      <geometry>
        <mesh filename="package://swerve_description/meshes/gripper/visual/finger.stl" scale="0.001 0.001 0.001"/>
      </geometry>
      <material name="">
        <color rgba="0.1 0.1 0.1 1"/>
      </material>
    </visual>
    <collision>
      <origin rpy="0 0 0" xyz="-0.091673 0.00875 -0.098336"/>
      <geometry>
        <mesh filename="package://swerve_description/meshes/gripper/collision/finger.stl" scale="0.001 0.001 0.001"/>
      </geometry>
    </collision>
  </link>
  <link name="left_finger_pad">
    <inertial>
      <origin rpy="0 0 0" xyz="-0.0022695421476374017 2.3166990085415594e-09 0.00779073905191241"/>
      <mass value="0.047823655444711066"/>
      <inertia ixx="5e-06" ixy="-0.0" ixz="0.0" iyy="4e-06" iyz="0.0" izz="2e-06"/>
    </inertial>
    <!-- <inertial>
          <origin xyz="-0.0022695421476374017 2.3166990085415594e-09 0.00779073905191241"
            rpy="0 0 0" />
          <mass value="${0.047823655444711066*0.14953484502}" />
          <inertia ixx="${5e-06*0.14953484502}" iyy="${4e-06*0.14953484502}" izz="${2e-06*0.14953484502}" ixy="${-0.0*0.14953484502}" iyz="${0.0*0.14953484502}" ixz="${0.0*0.14953484502}" />
        </inertial> -->
    <visual>
      <origin rpy="0 0 0" xyz="-0.0705 -0.0 -0.12056"/>
      <geometry>
        <mesh filename="package://swerve_description/meshes/gripper/visual/finger_pad.stl" scale="0.001 0.001 0.001"/>
      </geometry>
      <material name="">
        <color rgba="0.792156862745098 0.819607843137255 0.933333333333333 1"/>
      </material>
    </visual>
    <collision>
      <origin rpy="0 0 0" xyz="-0.0705 -0.0 -0.12056"/>
      <geometry>
        <mesh filename="package://swerve_description/meshes/gripper/collision/finger_pad.stl" scale="0.001 0.001 0.001"/>
      </geometry>
    </collision>
  </link>
  <joint name="left_finger_joint" type="revolute">
    <origin rpy="0 0.7800050960087859 0" xyz="0.055 0.0 0.0"/>
    <parent link="left_outer_knuckle"/>
    <child link="left_finger"/>
    <axis xyz="0.0 1.0 -0.0"/>
    <limit effort="50.0" lower="-0.01" upper="0.9400000000000001" velocity="2.0"/>
    <mimic joint="left_outer_knuckle_joint" multiplier="1" offset="0"/>
  </joint>
  <joint name="left_inner_knuckle_joint" type="revolute">
    <origin rpy="0 0.7907912307861107 0.0" xyz="0.0565 -0.0111 0.09116"/>
    <parent link="ag95_body"/>
    <child link="left_inner_knuckle"/>
    <axis xyz="0.0 -1.0 -0.0"/>
    <limit effort="50.0" lower="-0.01" upper="0.9400000000000001" velocity="2.0"/>
    <mimic joint="left_outer_knuckle_joint" multiplier="1" offset="0"/>
  </joint>
  <!-- This joint closes the kinematic loop. Since loops are not allowed in URDF, but they are
      allowed in SDF, this is an SDF fragment. -->
  <gazebo>
    <joint name="left_inner_knuckle_to_finger_joint" type="revolute">
      <pose> -0.020673 0 0.007524 0 0 0</pose>
      <axis>
        <xyz>0 1 0</xyz>
        <use_parent_model_frame>false</use_parent_model_frame>
      </axis>
      <parent>left_inner_knuckle</parent>
      <child>left_finger</child>
    </joint>
  </gazebo>
  <joint name="left_inner_finger_pad_joint" type="fixed">
    <origin rpy="0 0 0" xyz="-0.021173 0.00875 0.022224"/>
    <parent link="left_finger"/>
    <child link="left_finger_pad"/>
  </joint>
  <joint name="left_outer_knuckle_joint" type="revolute">
    <origin rpy="0 -0.7800050960087859 0" xyz="0.077173 0.00555 0.083636"/>
    <parent link="ag95_body"/>
    <child link="left_outer_knuckle"/>
    <axis xyz="-0.0 -1.0 0.0"/>
    <limit effort="50.0" lower="0" upper="0.93" velocity="2.0"/>
  </joint>
  <joint name="right_finger_joint" type="revolute">
    <origin rpy="0 0.7800050960087859 0" xyz="0.055 0.0 0.0"/>
    <parent link="right_outer_knuckle"/>
    <child link="right_finger"/>
    <axis xyz="0.0 1.0 -0.0"/>
    <limit effort="50.0" lower="-0.01" upper="0.9400000000000001" velocity="2.0"/>
    <mimic joint="left_outer_knuckle_joint" multiplier="1" offset="0"/>
  </joint>
  <joint name="right_inner_knuckle_joint" type="revolute">
    <origin rpy="0 0.7907912307861107 -3.141592653589793" xyz="0.0245 0.0397 0.09116"/>
    <parent link="ag95_body"/>
    <child link="right_inner_knuckle"/>
    <axis xyz="0.0 -1.0 -0.0"/>
    <limit effort="50.0" lower="-0.01" upper="0.9400000000000001" velocity="2.0"/>
    <mimic joint="left_outer_knuckle_joint" multiplier="1" offset="0"/>
  </joint>
  <!-- This joint closes the kinematic loop. Since loops are not allowed in URDF, but they are
      allowed in SDF, this is an SDF fragment. -->
  <gazebo>
    <joint name="right_inner_knuckle_to_finger_joint" type="revolute">
      <pose> -0.020673 0 0.007524 0 0 0</pose>
      <axis>
        <xyz>0 1 0</xyz>
        <use_parent_model_frame>false</use_parent_model_frame>
      </axis>
      <parent>right_inner_knuckle</parent>
      <child>right_finger</child>
    </joint>
  </gazebo>
  <joint name="right_inner_finger_pad_joint" type="fixed">
    <origin rpy="0 0 0" xyz="-0.021173 0.00875 0.022224"/>
    <parent link="right_finger"/>
    <child link="right_finger_pad"/>
  </joint>
  <link name="right_outer_knuckle">
    <inertial>
      <origin rpy="0 0 0" xyz="0.027678515816713697 0.008750002359538555 -4.432690447753185e-07"/>
      <mass value="0.0589066057773107"/>
      <inertia ixx="1e-06" ixy="0.0" ixz="-0.0" iyy="1.7e-05" iyz="0.0" izz="1.7e-05"/>
    </inertial>
    <!-- <inertial>
          <origin xyz="0.027678515816713697 0.008750002359538555 -4.432690447753185e-07" rpy="0 0 0" />
          <mass value="${0.0589066057773107*0.44684369179}" />
          <inertia ixx="${1e-06*0.44684369179}" iyy="${1.7e-05*0.44684369179}" izz="${1.7e-05*0.44684369179}" ixy="${0.0*0.44684369179}" iyz="${0.0*0.44684369179}" ixz="${-0.0*0.44684369179}" />
        </inertial> -->
    <visual>
      <origin rpy="0 0 0" xyz="-0.036673 0.00875 -0.098336"/>
      <geometry>
        <mesh filename="package://swerve_description/meshes/gripper/visual/outer_knuckle.stl" scale="0.001 0.001 0.001"/>
      </geometry>
      <material name="">
        <color rgba="0.1 0.1 0.1 1"/>
      </material>
    </visual>
    <collision>
      <origin rpy="0 0 0" xyz="-0.036673 0.00875 -0.098336"/>
      <geometry>
        <mesh filename="package://swerve_description/meshes/gripper/collision/outer_knuckle.stl" scale="0.001 0.001 0.001"/>
      </geometry>
    </collision>
  </link>
  <link name="right_inner_knuckle">
    <inertial>
      <origin rpy="0 0 0" xyz="-0.001773347637755853 0.025399999999162655 0.028950024725163018"/>
      <mass value="0.07116672022913799"/>
      <inertia ixx="3.7e-05" ixy="0.0" ixz="0.0" iyy="1.7e-05" iyz="-0.0" izz="2.1e-05"/>
    </inertial>
    <!-- <inertial>
          <origin xyz="-0.001773347637755853 0.025399999999162655 0.028950024725163018" rpy="0 0 0" />
          <mass value="${0.07116672022913799*0.44684369179}" />
          <inertia ixx="${3.7e-05*0.44684369179}" iyy="${1.7e-05*0.44684369179}" izz="${2.1e-05*0.44684369179}" ixy="${0.0*0.44684369179}" iyz="${-0.0*0.44684369179}" ixz="${0.0*0.44684369179}" />
        </inertial> -->
    <visual>
      <origin rpy="0 0 0" xyz="-0.016 0.0254 -0.10586"/>
      <geometry>
        <mesh filename="package://swerve_description/meshes/gripper/visual/inner_knuckle.stl" scale="0.001 0.001 0.001"/>
      </geometry>
      <material name="">
        <color rgba="0.1 0.1 0.1 1"/>
      </material>
    </visual>
    <collision>
      <origin rpy="0 0 0" xyz="-0.016 0.0254 -0.10586"/>
      <geometry>
        <mesh filename="package://swerve_description/meshes/gripper/collision/inner_knuckle.stl" scale="0.001 0.001 0.001"/>
      </geometry>
    </collision>
  </link>
  <link name="right_finger">
    <inertial>
      <origin rpy="0 0 0" xyz="-0.013763205176003518 0.008750002316393751 0.007315452388518454"/>
      <mass value="0.035304126564626004"/>
      <inertia ixx="2e-06" ixy="0.0" ixz="1e-06" iyy="4e-06" iyz="-0.0" izz="3e-06"/>
    </inertial>
    <!-- <inertial>
          <origin xyz="-0.013763205176003518 0.008750002316393751 0.007315452388518454" rpy="0 0 0" />
          <mass value="${0.035304126564626004*0.14953484502}" />
          <inertia ixx="${2e-06*0.14953484502}" iyy="${4e-06*0.14953484502}" izz="${3e-06*0.14953484502}" ixy="${0.0*0.14953484502}" iyz="${-0.0*0.14953484502}" ixz="${1e-06*0.14953484502}" />
        </inertial> -->
    <visual>
      <origin rpy="0 0 0" xyz="-0.091673 0.00875 -0.098336"/>
      <geometry>
        <mesh filename="package://swerve_description/meshes/gripper/visual/finger.stl" scale="0.001 0.001 0.001"/>
      </geometry>
      <material name="">
        <color rgba="0.1 0.1 0.1 1"/>
      </material>
    </visual>
    <collision>
      <origin rpy="0 0 0" xyz="-0.091673 0.00875 -0.098336"/>
      <geometry>
        <mesh filename="package://swerve_description/meshes/gripper/collision/finger.stl" scale="0.001 0.001 0.001"/>
      </geometry>
    </collision>
  </link>
  <link name="right_finger_pad">
    <inertial>
      <origin rpy="0 0 0" xyz="-0.0022695421476374017 2.3166990085415594e-09 0.00779073905191241"/>
      <mass value="0.047823655444711066"/>
      <inertia ixx="5e-06" ixy="-0.0" ixz="0.0" iyy="4e-06" iyz="0.0" izz="2e-06"/>
    </inertial>
    <!-- <inertial>
          <origin xyz="-0.0022695421476374017 2.3166990085415594e-09 0.00779073905191241"
            rpy="0 0 0" />
          <mass value="${0.047823655444711066*0.14953484502}" />
          <inertia ixx="${5e-06*0.14953484502}" iyy="${4e-06*0.14953484502}" izz="${2e-06*0.14953484502}" ixy="${-0.0*0.14953484502}" iyz="${0.0*0.14953484502}" ixz="${0.0*0.14953484502}" />
        </inertial> -->
    <visual>
      <origin rpy="0 0 0" xyz="-0.0705 -0.0 -0.12056"/>
      <geometry>
        <mesh filename="package://swerve_description/meshes/gripper/visual/finger_pad.stl" scale="0.001 0.001 0.001"/>
      </geometry>
      <material name="">
        <color rgba="0.792156862745098 0.819607843137255 0.933333333333333 1"/>
      </material>
    </visual>
    <collision>
      <origin rpy="0 0 0" xyz="-0.0705 -0.0 -0.12056"/>
      <geometry>
        <mesh filename="package://swerve_description/meshes/gripper/collision/finger_pad.stl" scale="0.001 0.001 0.001"/>
      </geometry>
    </collision>
  </link>
  <joint name="right_outer_knuckle_joint" type="revolute">
    <origin rpy="0 -0.7800050960087859 3.141592653589793" xyz="0.003827000000000011 0.02305 0.083636"/>
    <parent link="ag95_body"/>
    <child link="right_outer_knuckle"/>
    <axis xyz="-0.0 -1.0 0.0"/>
    <limit effort="50.0" lower="-0.01" upper="0.9400000000000001" velocity="2.0"/>
    <mimic joint="left_outer_knuckle_joint" multiplier="1" offset="0"/>
  </joint>
  <joint name="gripper_base_joint" type="fixed">
    <parent link="bracelet_link"/>
    <child link="ag95_base_link"/>
    <origin rpy="3.14159265358979 1.09937075168372E-32 3.14159265358979" xyz="0 0 -0.0640250000000001"/>
  </joint>
  <gazebo>
    <plugin filename="libgazebo_ros_control.so" name="gazebo_ros_control"/>
  </gazebo>
</robot>

